![[Pasted image 20240925194249.png]]
Блок finalyy выполняется всегда. И когда было выброшено исключение, и когда не было. И даже, если внутри catch было выброшено исключение. Он не выполнится только в том случае, если наше приложение выключится из розетки)


Внутри catch мы можем перечислить сразу несколько типов исключений, чтобы обработать их внутри catch.
![[Pasted image 20240925194554.png]]
### Несколько каверзных вопросов на эту тему
При вызове такого метода вернется 2
```java
private static int check() {  
    try {  
        return 3;  
    } finally {  
        return 2;   
    }  
}
```

Если код внутри try не выбрасывает checked exception, которое мы отлавливаем, то код не скомпилируется!
```java
private static int check() {  
    try {  
        return 3;  
    } catch (SQLException e) {  
            }  
}
```

Exception - не является checked exception! Поэтому мы код ниже скопилируется, даже если код внутри try не выбрасывает Exception:
```java
try {  
    return 3;  
} catch (Exception e) {  
  
} catch (Throwable e) {  
    }
```

Важно соблюдать иерархию при использовании catch. Сначала должны идти более низкие в иерархии исключения, т.е. более узкие, а только после них более высокие в иерархии. Поэтому код наверху скомпилируется, посольку Exception в иерархии ниже, чем Throwable и идет раньше Throwable. А код ниже не скомпилируется:

Ресурсы нужно закрывать, чтобы не было утечки памяти. Мы можем, например, оперативную память заполнить этим ресурсами, например, соединениями к чему-нибудь или открытыми файлами и наше приложение упадет. Или открывать постоянно соединения с БД, но не закрывать их. Тогда БД может просто перестать нам выдавать соединения. Поэтому ресурсы закрывать важно, это делается либо в finally, либо в блоке try with resource.
### Try with resources
Используется для закрытия каких-либо ресурсов. JVM автоматически вызывает метод close(), после выхода из блока try(т.е. либо когда все catch сработают и finally отработает, либо, если catch не справились, то перед тем, как выйти из функции с ошибкой закроются ресурсы). Поэтому класс, который используется внутри этого блока должен реализовывать интерфейс AutoCloseable или Closeable. Через ";" можно перечислять сразу несколько объектов.
```java
try (ResourceType resource = new ResourceType();
	 ResourceType resource1 = new ResourceType()) {
    // Использование ресурса
} catch (ExceptionType e) {
    // Обработка исключений
}

```

### Разница между Closeable и AutoCloseable
```java
public interface AutoCloseable {
    void close() throws Exception;
}

public interface Closeable extends AutoCloseable {
    void close() throws IOException;
}

```
Closeable - является более специфичным для работы с IOE. Т.е. он просто наследуется от AutoCloseable и вместо throws Exception, он выбрасывает IOException, который специчен как раз для IOE операций.

### Если внутри блока finally произойдет исключение, то оно подавит исключение, которое произошло в блоке try, т.е. снаружи будет исключение из finally, а не из try или catch(в случае, если в catch также выбрасывается исключение). Если мы хотим, чтобы исключение из try и исключение из finally передались, то нужно сохранить основное исключение в переменную и в блоке finally с помощью addSuppressed передать исключение из finally
```java
public class Example {
    public static void main(String[] args) {
        try {
            methodWithException();
        } catch (Exception e) {
            System.out.println("Caught: " + e.getMessage());
            for (Throwable suppressed : e.getSuppressed()) {
                System.out.println("Suppressed: " + suppressed.getMessage());
            }
        }
    }

    public static void methodWithException() throws Exception {
        Exception primaryException = null;
        try {
            throw new RuntimeException("Exception in try block");
        } catch (Exception e) {
            primaryException = e;
        } finally {
            Exception finallyException = new RuntimeException("Exception in finally block");
            if (primaryException != null) {
                primaryException.addSuppressed(finallyException);  // Добавляем исключение из finally как подавленное
                throw primaryException;  // Выбрасываем исходное исключение
            } else {
                throw finallyException;  // Если нет исключения в try/catch, выбрасываем из finally
            }
        }
    }
}

```

### Мы можем писать try finally без catch. Это полезно в ситуации c использованием lock. Чтобы в любом случае, разблокировать lock, если мы его заблокировали
![[Pasted image 20241022111916.png]]

### Checked exception мы должны обрабатывать всегда, а runtime - нет. Но может быть ситуация, когда мы хотим обрабатывать и runtime исключения, тогда это можно сделать следующими способами:
1. Вызвать метод setUncaughtExceptionHandler() у объекта класса Thread. Назначить такой обработчик только на 1 объект.
    
2. Определить свой класс ThreadGroup и переопределить метод uncaughtException().
    
3. Вызвать статический метод класса Thread — setDefaultUncaughtExceptionHandler(). - назначит такой обработчик для всех потоков.

Методы setUncaughtExceptionHandler() и setDefaultUncaughtExceptionHandler() принимают в качестве аргумента класс, который реализует интерфейс UncaughtExceptionHandler.

Этот интерфейс имеет всего один метод

void uncaughtException(Thread t, Throwable e)

Если выбросится исключение, которое мы не поймали, то вызовется обработчик, который мы назначили, сам же поток, в котором произошло исключение завершится.

**Завершение программы**: Если в потоке `main` произойдёт неперехваченное исключение, то, после обработки его через `uncaughtExceptionHandler`, программа завершится. Для других потоков — поток завершится, но остальные потоки продолжат выполнение, если они есть.

